Workbook

Sheet THE BOARD
A1: Option 1 | B1: SEQ. | C1: MAT. TYPE | D1: DATE | E1: HR | F1: SR | G1: ST | H1: Caged | I1: Non Caged | J1: CUT BY | K1: FIT BY | L1: Billed Status | M1: NOTES | N1: DRAWINGS | O1: KSS FILE | P1: 1 - ANGLE, 2 - PIPE, 3 - OTHER | Q1: MISC. | R1: MATERIAL STATUS | S1: Shipped Status
A2: PAX | B2: 246-95 | C2: 31 | D2: 45331 | E2: 20 | F2: 6 | G2: 8 | H2: 2 | K2: FB DONE | M2: NEEDS PIPE GR; HOLD
A3: PAX | B3: 246-96 | C3: 32 | D3: 45331 | E3: 20 | F3: 6 | G3: 8 | H3: 2 | K3: FB DONE | M3: NEEDS PIPE GR; HOLD
A4: TURNER | B4: GULCH Rev 1 | D4: 45331 | F4: 4
A5: STRUCTURAL STEEL | B5: 3233G LADDERS PO F21742 | C5: mebac ladder rungs | D5: 45338 | I5: 12
A6: PICOU FRADELLA | D6: 45341
A7: PAX | B7: 298-48M | D7: 45345 | E7: 8 | F7: 2 | G7: 2 | H7: 1
A8: EST | B8: PEABODY 6 | C8: TUBING | D8: 45352 | E8: 0 | F8: 47 | M8: PEABODY EST | N8: 6
A9: PAX | B9: 246-199M | C9: 34 | D9: 45352 | E9: 6 | H9: 1 | K9: FB DONE
A10: PAX | B10: 246-4CM | C10: 40 | D10: 45352 | E10: 30 | F10: 8 | G10: 8 | H10: 2 | N10: NO DRAWINGS AT 8/22
A11: PAX | B11: 246-4DM | C11: 42 | D11: 45352 | E11: 30 | F11: 8 | G11: 8 | H11: 2 | N11: NO DRAWINGS AT 8/22
A12: PAX | B12: 246-6CM | C12: 43 | D12: 45352 | E12: 6 | H12: 1 | M12: ANGLE | N12: NO DRAWINGS AT 8/22
A13: PAX | B13: 246-6DM | C13: 44 | D13: 45352 | E13: 6 | H13: 1 | M13: ANGLE | N13: NO DRAWINGS AT 8/22
A14: PAX | B14: 246-6EM | C14: 45 | D14: 45352 | E14: 6 | H14: 1 | M14: ANGLE | N14: NO DRAWINGS AT 7/26
A15: PAX | B15: 266-3CM | D15: 45352 | E15: 50 | F15: 40 | G15: 40
A16: PAX | B16: 246-182 | C16: 35 | D16: 45355 | E16: 40 | H16: 3 | M16: MISC STEEL FRAMES
A17: PAX | B17: 246-185 | C17: 36 | D17: 45355 | E17: 40 | H17: 3
A18: PAX | B18: 246-202 | C18: 37 | D18: 45355 | E18: 2 | F18: 2 | G18: 2 | M18: MISC FRAMES
A19: PAX | B19: 246-240 | C19: 38 | D19: 45355 | E19: 6
A20: PAX | B20: 246-250 | C20: 39 | D20: 45355 | E20: 6
A21: SOUTHLAND | B21: BECTHEL LIQUIFICATION 1023195 101R1-02 | D21: 45359 | E21: 65 | H21: 6 | J21: waiting on correct files | M21: PUT JOB PREFIX ON ALL TAGS 116A1 | R21: ordered materials
A22: PAX | B22: 246-14CM | C22: 46 | D22: 45359 | E22: 30 | F22: 10 | G22: 10 | H22: 2 | N22: NO DRAWINGS 8/23
A23: PAX | B23: 246-14DM | C23: 47 | D23: 45359 | E23: 30 | F23: 10 | G23: 10 | H23: 2 | N23: NO DRAWINGS 8/23
A24: PAX | B24: 246-14EM | C24: 48 | D24: 45359 | E24: 30 | F24: 6 | G24: 6 | H24: 2
A25: STRUCTURAL STEEL | B25: 3233G LADDERS (2ND SET) PO F21742 | C25: mebac ladder rungs | D25: 45366 | I25: 9
A26: PAX | B26: 318-3M | D26: 45366 | E26: 12 | F26: 4 | G26: 4 | M26: REVISIONS? 3002F1, 3002FP2, 3039P5, 3042S1, 3043S1
A27: Turner | B27: PEABODY 4 | C27: TUBING | D27: 45373 | F27: 47 | M27: PEABODY EST | N27: 4 | R27: MATERIALS?
A28: SOUTHLAND | B28: BECTHEL 1023195 R1-04 A/B | C28: 11.5 TONS | D28: 45373
A29: SOUTHLAND | B29: BECTHEL 1023195 D1-05 | C29: 4.2 TONS | D29: 45429
A30: PAX | B30: 246-15M | D30: tbd | E30: 11 | H30: 3 | M30: HOLD | N30: NO DRAWINGS 7/26
A31: PAX | B31: 277-1M.1 | D31: TBD | E31: 2 | F31: 4 | G31: 4 | M31: HOLD | N31: HOLD
A32: SOUTHLAND | B32: P208 REVISION HR 5664 | D32: TBD | M32: NEED DRAWINGS

Sheet Pivot Table 3
N1: W/ FRI
H2: 70 | I2: 20 | J2: RAILS DAYS | K2: 15 | L2: 6 | N2: DAYS IN MONTH
H3: HR DAYS | I3: SR DAYS | K3: STRINGER DAYS | L3: LADDER DAYS | M3: STR/CL DAYS
A4: Billed Status | B4: DATE | C4: SUM of HR | D4: SUM of SR | E4: SUM of ST | F4: SUM of Caged | G4: SUM of Non Caged | H4: =C4/$H$2 -> #VALUE! | I4: =D4/$I$2 -> #VALUE! | J4: =I4+H4 -> #VALUE! | K4: =E4/$K$2 -> #VALUE! | L4: =F4/$L$2 -> #VALUE! | M4: =L4+K4 -> #VALUE! | N4: 22
A5: (blank) | B5: Jan | C5: 5 | D5: 2 | H5: =C5/$H$2 -> 0.071428571 | I5: =D5/$I$2 -> 0.1 | J5: =I5+H5 -> 0.17142857 | K5: =E5/$K$2 -> 0 | L5: =F5/$L$2 -> 0 | M5: =L5+K5 -> 0 | N5: 20
B6: Feb | C6: 498 | D6: 111 | E6: 108 | F6: 38 | G6: 35 | H6: =C6/$H$2 -> 7.1142857 | I6: =D6/$I$2 -> 5.55 | J6: =I6+H6 -> 12.664286 | K6: =E6/$K$2 -> 7.2 | L6: =F6/$L$2 -> 6.3333333 | M6: =L6+K6 -> 13.533333 | N6: 23
H7: =C7/$H$2 -> 0 | I7: =D7/$I$2 -> 0 | J7: =I7+H7 -> 0 | K7: =E7/$K$2 -> 0 | L7: =F7/$L$2 -> 0 | M7: =L7+K7 -> 0 | N7: 3
H8: =C8/$H$2 -> 0 | I8: =D8/$I$2 -> 0 | J8: =I8+H8 -> 0 | K8: =E8/$K$2 -> 0 | L8: =F8/$L$2 -> 0 | M8: =L8+K8 -> 0
H9: =C9/$H$2 -> 0 | I9: =D9/$I$2 -> 0 | J9: =I9+H9 -> 0 | K9: =E9/$K$2 -> 0 | L9: =F9/$L$2 -> 0 | M9: =L9+K9 -> 0

Sheet DUE PIVOT
I1: 4.5 | J1: DAYS LEFT IN MONTH
E2: 70 | F2: 20 | G2: DAYS TOTAL | H2: WEEKS IN MONTH | I2: WRK DYS PER WK
A3: DATE | B3: SUM of SR | C3: SUM of HR | D3: SUM of Caged | E3: =C3/$E$2 -> #VALUE! | F3: =B3/$F$2 -> #VALUE! | G3: =F3+E3 -> #VALUE! | H3: 4 | I3: =H3*$I$1 -> 18 | J3: =I3-G3 -> #VALUE!
A4: tbd | B4: 4 | C4: 13 | D4: 3 | E4: =C4/$E$2 -> 0.18571429 | F4: =B4/$F$2 -> 0.2 | G4: =F4+E4 -> 0.38571429 | H4: 4 | I4: =H4*$I$1 -> 18 | J4: =I4-G4 -> 17.614286
A5: 45322 | B5: 2 | C5: 5 | E5: =C5/$E$2 -> 0.071428571 | F5: =B5/$F$2 -> 0.1 | G5: =F5+E5 -> 0.17142857 | H5: 4 | I5: =H5*$I$1 -> 18 | J5: =I5-G5 -> 17.828571
A6: 45323 | B6: 0 | C6: 0 | E6: =C6/$E$2 -> 0 | F6: =B6/$F$2 -> 0 | G6: =F6+E6 -> 0 | H6: 4 | I6: =H6*$I$1 -> 18 | J6: =I6-G6 -> 18
A7: 45324 | B7: 58 | C7: 261 | D7: 13 | E7: =C7/$E$2 -> 3.7285714 | F7: =B7/$F$2 -> 2.9 | G7: =F7+E7 -> 6.6285714 | H7: 4 | I7: =H7*$I$1 -> 18 | J7: =I7-G7 -> 11.371429
A8: 45331 | B8: 53 | C8: 221 | D8: 23 | E8: =C8/$E$2 -> 3.1571429
A9: 45338 | B9: 24 | C9: 186 | D9: 17
A10: 45341
A11: 45345 | B11: 12 | C11: 333 | D11: 17
A12: 45352 | B12: 63 | C12: 109 | D12: 15
A13: 45359 | B13: 26 | C13: 90 | D13: 6
A14: 45366 | B14: 4 | C14: 12
A15: 45373 | B15: 47 | C15: 0
A16: (blank) | B16: 0 | C16: 2
E19: Option 1 | F19: DATE | G19: SUM of HR | H19: SUM of SR
E20: RESERVE PAX | F20: 45323 | G20: 0 | H20: 0
E21: RESERVE PAX Total | G21: 0 | H21: 0
E22: Grand Total | G22: 0 | H22: 0
I26: 300 | J26: 36
I27: 320 | J27: 62
I28: =I26-I27 -> -20 | J28: =J26-J27 -> -26
I30: 238 | J30: 28
I31: =I30-I28 -> 258 | J31: =J30-J28 -> 54
J38: 3944
J39: =J38/12 -> 328.66667

Sheet Sheet4

Sheet PHONE
A1: ='THE BOARD'!A1 -> Option 1 | B1: ='THE BOARD'!B1 -> SEQ. | C1: ='THE BOARD'!D1 -> DATE | D1: ='THE BOARD'!E1 -> HR | E1: ='THE BOARD'!F1 -> SR | F1: ='THE BOARD'!G1 -> ST | G1: ='THE BOARD'!H1 -> Caged | H1: ='THE BOARD'!I1 -> Non Caged | J1: ='THE BOARD'!Q1 -> MISC.
A2: ='THE BOARD'!#REF! -> #REF! | B2: ='THE BOARD'!#REF! -> #REF! | C2: ='THE BOARD'!#REF! -> #REF! | D2: ='THE BOARD'!#REF! -> #REF! | E2: ='THE BOARD'!#REF! -> #REF! | F2: ='THE BOARD'!#REF! -> #REF! | G2: ='THE BOARD'!#REF! -> #REF! | H2: ='THE BOARD'!#REF! -> #REF! | J2: ='THE BOARD'!#REF! -> #REF!
A3: ='THE BOARD'!#REF! -> #REF! | B3: ='THE BOARD'!#REF! -> #REF! | C3: ='THE BOARD'!#REF! -> #REF! | D3: ='THE BOARD'!#REF! -> #REF! | E3: ='THE BOARD'!#REF! -> #REF! | F3: ='THE BOARD'!#REF! -> #REF! | G3: ='THE BOARD'!#REF! -> #REF! | H3: ='THE BOARD'!#REF! -> #REF! | J3: ='THE BOARD'!#REF! -> #REF!
A4: ='THE BOARD'!#REF! -> #REF! | B4: ='THE BOARD'!#REF! -> #REF! | C4: ='THE BOARD'!#REF! -> #REF! | D4: ='THE BOARD'!#REF! -> #REF! | E4: ='THE BOARD'!#REF! -> #REF! | F4: ='THE BOARD'!#REF! -> #REF! | G4: ='THE BOARD'!#REF! -> #REF! | H4: ='THE BOARD'!#REF! -> #REF! | J4: ='THE BOARD'!#REF! -> #REF!
A5: ='THE BOARD'!#REF! -> #REF! | B5: ='THE BOARD'!#REF! -> #REF! | C5: ='THE BOARD'!#REF! -> #REF! | D5: ='THE BOARD'!#REF! -> #REF! | E5: ='THE BOARD'!#REF! -> #REF! | F5: ='THE BOARD'!#REF! -> #REF! | G5: ='THE BOARD'!#REF! -> #REF! | H5: ='THE BOARD'!#REF! -> #REF! | J5: ='THE BOARD'!#REF! -> #REF!
A6: ='THE BOARD'!#REF! -> #REF! | B6: ='THE BOARD'!#REF! -> #REF! | C6: ='THE BOARD'!#REF! -> #REF! | D6: ='THE BOARD'!#REF! -> #REF! | E6: ='THE BOARD'!#REF! -> #REF! | F6: ='THE BOARD'!#REF! -> #REF! | G6: ='THE BOARD'!#REF! -> #REF! | H6: ='THE BOARD'!#REF! -> #REF! | J6: ='THE BOARD'!#REF! -> #REF!
A7: ='THE BOARD'!#REF! -> #REF! | B7: ='THE BOARD'!#REF! -> #REF! | C7: ='THE BOARD'!#REF! -> #REF! | D7: ='THE BOARD'!#REF! -> #REF! | E7: ='THE BOARD'!#REF! -> #REF! | F7: ='THE BOARD'!#REF! -> #REF! | G7: ='THE BOARD'!#REF! -> #REF! | H7: ='THE BOARD'!#REF! -> #REF! | J7: ='THE BOARD'!#REF! -> #REF!
A8: ='THE BOARD'!#REF! -> #REF! | B8: ='THE BOARD'!#REF! -> #REF! | C8: ='THE BOARD'!#REF! -> #REF! | D8: ='THE BOARD'!#REF! -> #REF! | E8: ='THE BOARD'!#REF! -> #REF! | F8: ='THE BOARD'!#REF! -> #REF! | G8: ='THE BOARD'!#REF! -> #REF! | H8: ='THE BOARD'!#REF! -> #REF! | J8: ='THE BOARD'!#REF! -> #REF!
A9: ='THE BOARD'!#REF! -> #REF! | B9: ='THE BOARD'!#REF! -> #REF! | C9: ='THE BOARD'!#REF! -> #REF! | D9: ='THE BOARD'!#REF! -> #REF! | E9: ='THE BOARD'!#REF! -> #REF! | F9: ='THE BOARD'!#REF! -> #REF! | G9: ='THE BOARD'!#REF! -> #REF! | H9: ='THE BOARD'!#REF! -> #REF! | J9: ='THE BOARD'!#REF! -> #REF!
A10: ='THE BOARD'!#REF! -> #REF! | B10: ='THE BOARD'!#REF! -> #REF! | C10: ='THE BOARD'!#REF! -> #REF! | D10: ='THE BOARD'!#REF! -> #REF! | E10: ='THE BOARD'!#REF! -> #REF! | F10: ='THE BOARD'!#REF! -> #REF! | G10: ='THE BOARD'!#REF! -> #REF! | H10: ='THE BOARD'!#REF! -> #REF! | J10: ='THE BOARD'!#REF! -> #REF!
A11: ='THE BOARD'!#REF! -> #REF! | B11: ='THE BOARD'!#REF! -> #REF! | C11: ='THE BOARD'!#REF! -> #REF! | D11: ='THE BOARD'!#REF! -> #REF! | E11: ='THE BOARD'!#REF! -> #REF! | F11: ='THE BOARD'!#REF! -> #REF! | G11: ='THE BOARD'!#REF! -> #REF! | H11: ='THE BOARD'!#REF! -> #REF! | J11: ='THE BOARD'!#REF! -> #REF!
A12: ='THE BOARD'!#REF! -> #REF! | B12: ='THE BOARD'!#REF! -> #REF! | C12: ='THE BOARD'!#REF! -> #REF! | D12: ='THE BOARD'!#REF! -> #REF! | E12: ='THE BOARD'!#REF! -> #REF! | F12: ='THE BOARD'!#REF! -> #REF! | G12: ='THE BOARD'!#REF! -> #REF! | H12: ='THE BOARD'!#REF! -> #REF! | J12: ='THE BOARD'!#REF! -> #REF!
A13: ='THE BOARD'!#REF! -> #REF! | B13: ='THE BOARD'!#REF! -> #REF! | C13: ='THE BOARD'!#REF! -> #REF! | D13: ='THE BOARD'!#REF! -> #REF! | E13: ='THE BOARD'!#REF! -> #REF! | F13: ='THE BOARD'!#REF! -> #REF! | G13: ='THE BOARD'!#REF! -> #REF! | H13: ='THE BOARD'!#REF! -> #REF! | J13: ='THE BOARD'!#REF! -> #REF!
... A108: ='THE BOARD'!#REF! -> #REF! | B108: ='THE BOARD'!#REF! -> #REF! | C108: ='THE BOARD'!#REF! -> #REF! | D108: ='THE BOARD'!#REF! -> #REF! | E108: ='THE BOARD'!#REF! -> #REF! | F108: ='THE BOARD'!#REF! -> #REF! | G108: ='THE BOARD'!#REF! -> #REF! | H108: ='THE BOARD'!#REF! -> #REF! | J108: ='THE BOARD'!#REF! -> #REF!
A109: =#REF! -> #REF! | B109: =#REF! -> #REF! | C109: =#REF! -> #REF! | D109: =#REF! -> #REF! | E109: =#REF! -> #REF! | F109: =#REF! -> #REF! | G109: =#REF! -> #REF! | H109: =#REF! -> #REF! | J109: =#REF! -> #REF!
A110: ='THE BOARD'!#REF! -> #REF! | B110: ='THE BOARD'!#REF! -> #REF! | C110: ='THE BOARD'!#REF! -> #REF! | D110: ='THE BOARD'!#REF! -> #REF! | E110: ='THE BOARD'!#REF! -> #REF! | F110: ='THE BOARD'!#REF! -> #REF! | G110: ='THE BOARD'!#REF! -> #REF! | H110: ='THE BOARD'!#REF! -> #REF! | J110: ='THE BOARD'!#REF! -> #REF!
A111: =#REF! -> #REF! | B111: =#REF! -> #REF! | C111: =#REF! -> #REF! | D111: =#REF! -> #REF! | E111: =#REF! -> #REF! | F111: =#REF! -> #REF! | G111: =#REF! -> #REF! | H111: =#REF! -> #REF! | J111: =#REF! -> #REF!
A112: ='THE BOARD'!#REF! -> #REF! | B112: ='THE BOARD'!#REF! -> #REF! | C112: ='THE BOARD'!#REF! -> #REF! | D112: ='THE BOARD'!#REF! -> #REF! | E112: ='THE BOARD'!#REF! -> #REF! | F112: ='THE BOARD'!#REF! -> #REF! | G112: ='THE BOARD'!#REF! -> #REF! | H112: ='THE BOARD'!#REF! -> #REF! | J112: ='THE BOARD'!#REF! -> #REF!
A113: ='THE BOARD'!#REF! -> #REF! | B113: ='THE BOARD'!#REF! -> #REF! | C113: ='THE BOARD'!#REF! -> #REF! | D113: ='THE BOARD'!#REF! -> #REF! | E113: ='THE BOARD'!#REF! -> #REF! | F113: ='THE BOARD'!#REF! -> #REF! | G113: ='THE BOARD'!#REF! -> #REF! | H113: ='THE BOARD'!#REF! -> #REF! | J113: ='THE BOARD'!#REF! -> #REF!
A114: ='THE BOARD'!#REF! -> #REF! | B114: ='THE BOARD'!#REF! -> #REF! | C114: ='THE BOARD'!#REF! -> #REF! | D114: ='THE BOARD'!#REF! -> #REF! | E114: ='THE BOARD'!#REF! -> #REF! | F114: ='THE BOARD'!#REF! -> #REF! | G114: ='THE BOARD'!#REF! -> #REF! | H114: ='THE BOARD'!#REF! -> #REF! | J114: ='THE BOARD'!#REF! -> #REF!
A115: ='THE BOARD'!#REF! -> #REF! | B115: ='THE BOARD'!#REF! -> #REF! | C115: ='THE BOARD'!#REF! -> #REF! | D115: ='THE BOARD'!#REF! -> #REF! | E115: ='THE BOARD'!#REF! -> #REF! | F115: ='THE BOARD'!#REF! -> #REF! | G115: ='THE BOARD'!#REF! -> #REF! | H115: ='THE BOARD'!#REF! -> #REF! | J115: ='THE BOARD'!#REF! -> #REF!
A116: ='THE BOARD'!#REF! -> #REF! | B116: ='THE BOARD'!#REF! -> #REF! | C116: ='THE BOARD'!#REF! -> #REF! | D116: ='THE BOARD'!#REF! -> #REF! | E116: ='THE BOARD'!#REF! -> #REF! | F116: ='THE BOARD'!#REF! -> #REF! | G116: ='THE BOARD'!#REF! -> #REF! | H116: ='THE BOARD'!#REF! -> #REF! | J116: ='THE BOARD'!#REF! -> #REF!
A117: ='THE BOARD'!#REF! -> #REF! | B117: ='THE BOARD'!#REF! -> #REF! | C117: ='THE BOARD'!#REF! -> #REF! | D117: ='THE BOARD'!#REF! -> #REF! | E117: ='THE BOARD'!#REF! -> #REF! | F117: ='THE BOARD'!#REF! -> #REF! | G117: ='THE BOARD'!#REF! -> #REF! | H117: ='THE BOARD'!#REF! -> #REF! | J117: ='THE BOARD'!#REF! -> #REF!
A118: ='THE BOARD'!#REF! -> #REF! | B118: ='THE BOARD'!#REF! -> #REF! | C118: ='THE BOARD'!#REF! -> #REF! | D118: ='THE BOARD'!#REF! -> #REF! | E118: ='THE BOARD'!#REF! -> #REF! | F118: ='THE BOARD'!#REF! -> #REF! | G118: ='THE BOARD'!#REF! -> #REF! | H118: ='THE BOARD'!#REF! -> #REF! | J118: ='THE BOARD'!#REF! -> #REF!
A119: ='THE BOARD'!#REF! -> #REF! | B119: ='THE BOARD'!#REF! -> #REF! | C119: ='THE BOARD'!#REF! -> #REF! | D119: ='THE BOARD'!#REF! -> #REF! | E119: ='THE BOARD'!#REF! -> #REF! | F119: ='THE BOARD'!#REF! -> #REF! | G119: ='THE BOARD'!#REF! -> #REF! | H119: ='THE BOARD'!#REF! -> #REF! | J119: ='THE BOARD'!#REF! -> #REF!
A120: =#REF! -> #REF! | B120: =#REF! -> #REF! | C120: =#REF! -> #REF! | D120: =#REF! -> #REF! | E120: =#REF! -> #REF! | F120: =#REF! -> #REF! | G120: =#REF! -> #REF! | H120: =#REF! -> #REF! | J120: =#REF! -> #REF!
A121: ='THE BOARD'!#REF! -> #REF! | B121: ='THE BOARD'!#REF! -> #REF! | C121: ='THE BOARD'!#REF! -> #REF! | D121: ='THE BOARD'!#REF! -> #REF! | E121: ='THE BOARD'!#REF! -> #REF! | F121: ='THE BOARD'!#REF! -> #REF! | G121: ='THE BOARD'!#REF! -> #REF! | H121: ='THE BOARD'!#REF! -> #REF! | J121: ='THE BOARD'!#REF! -> #REF!
A122: ='THE BOARD'!#REF! -> #REF! | B122: ='THE BOARD'!#REF! -> #REF! | C122: ='THE BOARD'!#REF! -> #REF! | D122: ='THE BOARD'!#REF! -> #REF! | E122: ='THE BOARD'!#REF! -> #REF! | F122: ='THE BOARD'!#REF! -> #REF! | G122: ='THE BOARD'!#REF! -> #REF! | H122: ='THE BOARD'!#REF! -> #REF! | J122: ='THE BOARD'!#REF! -> #REF!
A123: ='THE BOARD'!#REF! -> #REF! | B123: ='THE BOARD'!#REF! -> #REF! | C123: ='THE BOARD'!#REF! -> #REF! | D123: ='THE BOARD'!#REF! -> #REF! | E123: ='THE BOARD'!#REF! -> #REF! | F123: ='THE BOARD'!#REF! -> #REF! | G123: ='THE BOARD'!#REF! -> #REF! | H123: ='THE BOARD'!#REF! -> #REF! | J123: ='THE BOARD'!#REF! -> #REF!
A124: =#REF! -> #REF! | B124: =#REF! -> #REF! | C124: =#REF! -> #REF! | D124: =#REF! -> #REF! | E124: =#REF! -> #REF! | F124: =#REF! -> #REF! | G124: =#REF! -> #REF! | H124: =#REF! -> #REF! | J124: =#REF! -> #REF!
A125: ='THE BOARD'!#REF! -> #REF! | B125: ='THE BOARD'!#REF! -> #REF! | C125: ='THE BOARD'!#REF! -> #REF! | D125: ='THE BOARD'!#REF! -> #REF! | E125: ='THE BOARD'!#REF! -> #REF! | F125: ='THE BOARD'!#REF! -> #REF! | G125: ='THE BOARD'!#REF! -> #REF! | H125: ='THE BOARD'!#REF! -> #REF! | J125: ='THE BOARD'!#REF! -> #REF!
A126: ='THE BOARD'!#REF! -> #REF! | B126: ='THE BOARD'!#REF! -> #REF! | C126: ='THE BOARD'!#REF! -> #REF! | D126: ='THE BOARD'!#REF! -> #REF! | E126: ='THE BOARD'!#REF! -> #REF! | F126: ='THE BOARD'!#REF! -> #REF! | G126: ='THE BOARD'!#REF! -> #REF! | H126: ='THE BOARD'!#REF! -> #REF! | J126: ='THE BOARD'!#REF! -> #REF!
A127: ='THE BOARD'!#REF! -> #REF! | B127: ='THE BOARD'!#REF! -> #REF! | C127: ='THE BOARD'!#REF! -> #REF! | D127: ='THE BOARD'!#REF! -> #REF! | E127: ='THE BOARD'!#REF! -> #REF! | F127: ='THE BOARD'!#REF! -> #REF! | G127: ='THE BOARD'!#REF! -> #REF! | H127: ='THE BOARD'!#REF! -> #REF! | J127: ='THE BOARD'!#REF! -> #REF!
A128: ='THE BOARD'!#REF! -> #REF! | B128: ='THE BOARD'!#REF! -> #REF! | C128: ='THE BOARD'!#REF! -> #REF! | D128: ='THE BOARD'!#REF! -> #REF! | E128: ='THE BOARD'!#REF! -> #REF! | F128: ='THE BOARD'!#REF! -> #REF! | G128: ='THE BOARD'!#REF! -> #REF! | H128: ='THE BOARD'!#REF! -> #REF! | J128: ='THE BOARD'!#REF! -> #REF!
A129: ='THE BOARD'!#REF! -> #REF! | B129: ='THE BOARD'!#REF! -> #REF! | C129: ='THE BOARD'!#REF! -> #REF! | D129: ='THE BOARD'!#REF! -> #REF! | E129: ='THE BOARD'!#REF! -> #REF! | F129: ='THE BOARD'!#REF! -> #REF! | G129: ='THE BOARD'!#REF! -> #REF! | H129: ='THE BOARD'!#REF! -> #REF! | J129: ='THE BOARD'!#REF! -> #REF!
A130: ='THE BOARD'!#REF! -> #REF! | B130: ='THE BOARD'!#REF! -> #REF! | C130: ='THE BOARD'!#REF! -> #REF! | D130: ='THE BOARD'!#REF! -> #REF! | E130: ='THE BOARD'!#REF! -> #REF! | F130: ='THE BOARD'!#REF! -> #REF! | G130: ='THE BOARD'!#REF! -> #REF! | H130: ='THE BOARD'!#REF! -> #REF! | J130: ='THE BOARD'!#REF! -> #REF!
A131: ='THE BOARD'!#REF! -> #REF! | B131: ='THE BOARD'!#REF! -> #REF! | C131: ='THE BOARD'!#REF! -> #REF! | D131: ='THE BOARD'!#REF! -> #REF! | E131: ='THE BOARD'!#REF! -> #REF! | F131: ='THE BOARD'!#REF! -> #REF! | G131: ='THE BOARD'!#REF! -> #REF! | H131: ='THE BOARD'!#REF! -> #REF! | J131: ='THE BOARD'!#REF! -> #REF!
A132: ='THE BOARD'!#REF! -> #REF! | B132: ='THE BOARD'!#REF! -> #REF! | C132: ='THE BOARD'!#REF! -> #REF! | D132: ='THE BOARD'!#REF! -> #REF! | E132: ='THE BOARD'!#REF! -> #REF! | F132: ='THE BOARD'!#REF! -> #REF! | G132: ='THE BOARD'!#REF! -> #REF! | H132: ='THE BOARD'!#REF! -> #REF! | J132: ='THE BOARD'!#REF! -> #REF!
A133: ='THE BOARD'!#REF! -> #REF! | B133: ='THE BOARD'!#REF! -> #REF! | C133: ='THE BOARD'!#REF! -> #REF! | D133: ='THE BOARD'!#REF! -> #REF! | E133: ='THE BOARD'!#REF! -> #REF! | F133: ='THE BOARD'!#REF! -> #REF! | G133: ='THE BOARD'!#REF! -> #REF! | H133: ='THE BOARD'!#REF! -> #REF! | J133: ='THE BOARD'!#REF! -> #REF!
A134: ='THE BOARD'!#REF! -> #REF! | B134: ='THE BOARD'!#REF! -> #REF! | C134: ='THE BOARD'!#REF! -> #REF! | D134: ='THE BOARD'!#REF! -> #REF! | E134: ='THE BOARD'!#REF! -> #REF! | F134: ='THE BOARD'!#REF! -> #REF! | G134: ='THE BOARD'!#REF! -> #REF! | H134: ='THE BOARD'!#REF! -> #REF! | J134: ='THE BOARD'!#REF! -> #REF!
...

Sheet export
A1: v9iajm6jgrvgo3u1s7h6v3n0co@group.calendar.google.com
A2: ='THE BOARD'!#REF! -> #REF! | B2: ='THE BOARD'!#REF! -> #REF! | C2: =IF('THE BOARD'!#REF! = "NESTED","",IF('THE BOARD'!#REF!<>"",'THE BOARD'!#REF!+0.72,"")) -> #REF! | D2: =IF(C2<>"", IF('THE BOARD'!#REF! = "NESTED","",'THE BOARD'!#REF! + IF(C2<>"", 0.72,0)),"") -> #REF! | E2: ='THE BOARD'!#REF! -> #REF! | F2: ='THE BOARD'!#REF! -> #REF! | G2: ='THE BOARD'!#REF! -> #REF! | H2: ='THE BOARD'!#REF! -> #REF! | I2: ='THE BOARD'!#REF! -> #REF! | J2: ='THE BOARD'!#REF! -> #REF! | K2: ='THE BOARD'!#REF! -> #REF!
A3: ='THE BOARD'!#REF! -> #REF! | B3: ='THE BOARD'!#REF! -> #REF! | C3: =IF('THE BOARD'!#REF! = "NESTED","",IF('THE BOARD'!#REF!<>"",'THE BOARD'!#REF!+0.72,"")) -> #REF! | D3: =IF(C3<>"", IF('THE BOARD'!#REF! = "NESTED","",'THE BOARD'!#REF! + IF(C3<>"", 0.72,0)),"") -> #REF! | E3: ='THE BOARD'!#REF! -> #REF! | F3: ='THE BOARD'!#REF! -> #REF! | G3: ='THE BOARD'!#REF! -> #REF! | H3: ='THE BOARD'!#REF! -> #REF! | I3: ='THE BOARD'!#REF! -> #REF! | J3: ='THE BOARD'!#REF! -> #REF! | K3: ='THE BOARD'!#REF! -> #REF!
A4: ='THE BOARD'!#REF! -> #REF! | B4: ='THE BOARD'!#REF! -> #REF! | C4: =IF('THE BOARD'!#REF! = "NESTED","",IF('THE BOARD'!#REF!<>"",'THE BOARD'!#REF!+0.72,"")) -> #REF! | D4: =IF(C4<>"", IF('THE BOARD'!#REF! = "NESTED","",'THE BOARD'!#REF! + IF(C4<>"", 0.72,0)),"") -> #REF! | E4: ='THE BOARD'!#REF! -> #REF! | F4: ='THE BOARD'!#REF! -> #REF! | G4: ='THE BOARD'!#REF! -> #REF! | H4: ='THE BOARD'!#REF! -> #REF! | I4: ='THE BOARD'!#REF! -> #REF! | J4: ='THE BOARD'!#REF! -> #REF! | K4: ='THE BOARD'!#REF! -> #REF!
A5: ='THE BOARD'!#REF! -> #REF! | B5: ='THE BOARD'!#REF! -> #REF! | C5: =IF('THE BOARD'!#REF! = "NESTED","",IF('THE BOARD'!#REF!<>"",'THE BOARD'!#REF!+0.72,"")) -> #REF! | D5: =IF(C5<>"", IF('THE BOARD'!#REF! = "NESTED","",'THE BOARD'!#REF! + IF(C5<>"", 0.72,0)),"") -> #REF! | E5: ='THE BOARD'!#REF! -> #REF! | F5: ='THE BOARD'!#REF! -> #REF! | G5: ='THE BOARD'!#REF! -> #REF! | H5: ='THE BOARD'!#REF! -> #REF! | I5: ='THE BOARD'!#REF! -> #REF! | J5: ='THE BOARD'!#REF! -> #REF! | K5: ='THE BOARD'!#REF! -> #REF!
A6: ='THE BOARD'!#REF! -> #REF! | B6: ='THE BOARD'!#REF! -> #REF! | C6: =IF('THE BOARD'!#REF! = "NESTED","",IF('THE BOARD'!#REF!<>"",'THE BOARD'!#REF!+0.72,"")) -> #REF! | D6: =IF(C6<>"", IF('THE BOARD'!#REF! = "NESTED","",'THE BOARD'!#REF! + IF(C6<>"", 0.72,0)),"") -> #REF! | E6: ='THE BOARD'!#REF! -> #REF! | F6: ='THE BOARD'!#REF! -> #REF! | G6: ='THE BOARD'!#REF! -> #REF! | H6: ='THE BOARD'!#REF! -> #REF! | I6: ='THE BOARD'!#REF! -> #REF! | J6: ='THE BOARD'!#REF! -> #REF! | K6: ='THE BOARD'!#REF! -> #REF!
A7: ='THE BOARD'!#REF! -> #REF! | B7: ='THE BOARD'!#REF! -> #REF! | C7: =IF('THE BOARD'!#REF! = "NESTED","",IF('THE BOARD'!#REF!<>"",'THE BOARD'!#REF!+0.72,"")) -> #REF! | D7: =IF(C7<>"", IF('THE BOARD'!#REF! = "NESTED","",'THE BOARD'!#REF! + IF(C7<>"", 0.72,0)),"") -> #REF! | E7: ='THE BOARD'!#REF! -> #REF! | F7: ='THE BOARD'!#REF! -> #REF! | G7: ='THE BOARD'!#REF! -> #REF! | H7: ='THE BOARD'!#REF! -> #REF! | I7: ='THE BOARD'!#REF! -> #REF! | J7: ='THE BOARD'!#REF! -> #REF! | K7: ='THE BOARD'!#REF! -> #REF!
A8: ='THE BOARD'!#REF! -> #REF! | B8: ='THE BOARD'!#REF! -> #REF! | C8: =IF('THE BOARD'!#REF! = "NESTED","",IF('THE BOARD'!#REF!<>"",'THE BOARD'!#REF!+0.72,"")) -> #REF! | D8: =IF(C8<>"", IF('THE BOARD'!#REF! = "NESTED","",'THE BOARD'!#REF! + IF(C8<>"", 0.72,0)),"") -> #REF! | E8: ='THE BOARD'!#REF! -> #REF! | F8: ='THE BOARD'!#REF! -> #REF! | G8: ='THE BOARD'!#REF! -> #REF! | H8: ='THE BOARD'!#REF! -> #REF! | I8: ='THE BOARD'!#REF! -> #REF! | J8: ='THE BOARD'!#REF! -> #REF! | K8: ='THE BOARD'!#REF! -> #REF!
A9: ='THE BOARD'!#REF! -> #REF! | B9: ='THE BOARD'!#REF! -> #REF! | C9: =IF('THE BOARD'!#REF! = "NESTED","",IF('THE BOARD'!#REF!<>"",'THE BOARD'!#REF!+0.72,"")) -> #REF! | D9: =IF(C9<>"", IF('THE BOARD'!#REF! = "NESTED","",'THE BOARD'!#REF! + IF(C9<>"", 0.72,0)),"") -> #REF! | E9: ='THE BOARD'!#REF! -> #REF! | F9: ='THE BOARD'!#REF! -> #REF! | G9: ='THE BOARD'!#REF! -> #REF! | H9: ='THE BOARD'!#REF! -> #REF! | I9: ='THE BOARD'!#REF! -> #REF! | J9: ='THE BOARD'!#REF! -> #REF! | K9: ='THE BOARD'!#REF! -> #REF!
A10: ='THE BOARD'!#REF! -> #REF! | B10: ='THE BOARD'!#REF! -> #REF! | C10: =IF('THE BOARD'!#REF! = "NESTED","",IF('THE BOARD'!#REF!<>"",'THE BOARD'!#REF!+0.72,"")) -> #REF! | D10: =IF(C10<>"", IF('THE BOARD'!#REF! = "NESTED","",'THE BOARD'!#REF! + IF(C10<>"", 0.72,0)),"") -> #REF! | E10: ='THE BOARD'!#REF! -> #REF! | F10: ='THE BOARD'!#REF! -> #REF! | G10: ='THE BOARD'!#REF! -> #REF! | H10: ='THE BOARD'!#REF! -> #REF! | I10: ='THE BOARD'!#REF! -> #REF! | J10: ='THE BOARD'!#REF! -> #REF! | K10: ='THE BOARD'!#REF! -> #REF!
A11: ='THE BOARD'!#REF! -> #REF! | B11: ='THE BOARD'!#REF! -> #REF! | C11: =IF('THE BOARD'!#REF! = "NESTED","",IF('THE BOARD'!#REF!<>"",'THE BOARD'!#REF!+0.72,"")) -> #REF! | D11: =IF(C11<>"", IF('THE BOARD'!#REF! = "NESTED","",'THE BOARD'!#REF! + IF(C11<>"", 0.72,0)),"") -> #REF! | E11: ='THE BOARD'!#REF! -> #REF! | F11: ='THE BOARD'!#REF! -> #REF! | G11: ='THE BOARD'!#REF! -> #REF! | H11: ='THE BOARD'!#REF! -> #REF! | I11: ='THE BOARD'!#REF! -> #REF! | J11: ='THE BOARD'!#REF! -> #REF! | K11: ='THE BOARD'!#REF! -> #REF!
A12: ='THE BOARD'!#REF! -> #REF! | B12: ='THE BOARD'!#REF! -> #REF! | C12: =IF('THE BOARD'!#REF! = "NESTED","",IF('THE BOARD'!#REF!<>"",'THE BOARD'!#REF!+0.72,"")) -> #REF! | D12: =IF(C12<>"", IF('THE BOARD'!#REF! = "NESTED","",'THE BOARD'!#REF! + IF(C12<>"", 0.72,0)),"") -> #REF! | E12: ='THE BOARD'!#REF! -> #REF! | F12: ='THE BOARD'!#REF! -> #REF! | G12: ='THE BOARD'!#REF! -> #REF! | H12: ='THE BOARD'!#REF! -> #REF! | I12: ='THE BOARD'!#REF! -> #REF! | J12: ='THE BOARD'!#REF! -> #REF! | K12: ='THE BOARD'!#REF! -> #REF!
A13: ='THE BOARD'!#REF! -> #REF! | B13: ='THE BOARD'!#REF! -> #REF! | C13: =IF('THE BOARD'!#REF! = "NESTED","",IF('THE BOARD'!#REF!<>"",'THE BOARD'!#REF!+0.72,"")) -> #REF! | D13: =IF(C13<>"", IF('THE BOARD'!#REF! = "NESTED","",'THE BOARD'!#REF! + IF(C13<>"", 0.72,0)),"") -> #REF! | E13: ='THE BOARD'!#REF! -> #REF! | F13: ='THE BOARD'!#REF! -> #REF! | G13: ='THE BOARD'!#REF! -> #REF! | H13: ='THE BOARD'!#REF! -> #REF! | I13: ='THE BOARD'!#REF! -> #REF! | J13: ='THE BOARD'!#REF! -> #REF! | K13: ='THE BOARD'!#REF! -> #REF!
... A127: ='THE BOARD'!#REF! -> #REF! | B127: ='THE BOARD'!#REF! -> #REF! | C127: =IF('THE BOARD'!#REF! = "NESTED","",IF('THE BOARD'!#REF!<>"",'THE BOARD'!#REF!+0.72,"")) -> #REF! | D127: =IF(C127<>"", IF('THE BOARD'!#REF! = "NESTED","",'THE BOARD'!#REF! + IF(C127<>"", 0.72,0)),"") -> #REF! | E127: ='THE BOARD'!#REF! -> #REF! | F127: ='THE BOARD'!#REF! -> #REF! | G127: ='THE BOARD'!#REF! -> #REF! | H127: ='THE BOARD'!#REF! -> #REF! | I127: ='THE BOARD'!#REF! -> #REF! | J127: ='THE BOARD'!#REF! -> #REF! | K127: ='THE BOARD'!#REF! -> #REF!
A128: =#REF! -> #REF! | B128: =#REF! -> #REF! | C128: =IF(#REF! = "NESTED","",IF(#REF!<>"",#REF!+0.72,"")) -> #REF! | D128: =IF(C128<>"", IF(#REF! = "NESTED","",#REF! + IF(C128<>"", 0.72,0)),"") -> #REF! | E128: =#REF! -> #REF! | F128: =#REF! -> #REF! | G128: =#REF! -> #REF! | H128: =#REF! -> #REF! | I128: =#REF! -> #REF! | J128: =#REF! -> #REF! | K128: =#REF! -> #REF!
A129: ='THE BOARD'!#REF! -> #REF! | B129: ='THE BOARD'!#REF! -> #REF! | C129: =IF('THE BOARD'!#REF! = "NESTED","",IF('THE BOARD'!#REF!<>"",'THE BOARD'!#REF!+0.72,"")) -> #REF! | D129: =IF(C129<>"", IF('THE BOARD'!#REF! = "NESTED","",'THE BOARD'!#REF! + IF(C129<>"", 0.72,0)),"") -> #REF! | E129: ='THE BOARD'!#REF! -> #REF! | F129: ='THE BOARD'!#REF! -> #REF! | G129: ='THE BOARD'!#REF! -> #REF! | H129: ='THE BOARD'!#REF! -> #REF! | I129: ='THE BOARD'!#REF! -> #REF! | J129: ='THE BOARD'!#REF! -> #REF! | K129: ='THE BOARD'!#REF! -> #REF!
A130: ='THE BOARD'!#REF! -> #REF! | B130: ='THE BOARD'!#REF! -> #REF! | C130: =IF('THE BOARD'!#REF! = "NESTED","",IF('THE BOARD'!#REF!<>"",'THE BOARD'!#REF!+0.72,"")) -> #REF! | D130: =IF(C130<>"", IF('THE BOARD'!#REF! = "NESTED","",'THE BOARD'!#REF! + IF(C130<>"", 0.72,0)),"") -> #REF! | E130: ='THE BOARD'!#REF! -> #REF! | F130: ='THE BOARD'!#REF! -> #REF! | G130: ='THE BOARD'!#REF! -> #REF! | H130: ='THE BOARD'!#REF! -> #REF! | I130: ='THE BOARD'!#REF! -> #REF! | J130: ='THE BOARD'!#REF! -> #REF! | K130: ='THE BOARD'!#REF! -> #REF!
A131: ='THE BOARD'!#REF! -> #REF! | B131: ='THE BOARD'!#REF! -> #REF! | C131: =IF('THE BOARD'!#REF! = "NESTED","",IF('THE BOARD'!#REF!<>"",'THE BOARD'!#REF!+0.72,"")) -> #REF! | D131: =IF(C131<>"", IF('THE BOARD'!#REF! = "NESTED","",'THE BOARD'!#REF! + IF(C131<>"", 0.72,0)),"") -> #REF! | E131: ='THE BOARD'!#REF! -> #REF! | F131: ='THE BOARD'!#REF! -> #REF! | G131: ='THE BOARD'!#REF! -> #REF! | H131: ='THE BOARD'!#REF! -> #REF! | I131: ='THE BOARD'!#REF! -> #REF! | J131: ='THE BOARD'!#REF! -> #REF! | K131: ='THE BOARD'!#REF! -> #REF!
A132: ='THE BOARD'!#REF! -> #REF! | B132: ='THE BOARD'!#REF! -> #REF! | C132: =IF('THE BOARD'!#REF! = "NESTED","",IF('THE BOARD'!#REF!<>"",'THE BOARD'!#REF!+0.72,"")) -> #REF! | D132: =IF(C132<>"", IF('THE BOARD'!#REF! = "NESTED","",'THE BOARD'!#REF! + IF(C132<>"", 0.72,0)),"") -> #REF! | E132: ='THE BOARD'!#REF! -> #REF! | F132: ='THE BOARD'!#REF! -> #REF! | G132: ='THE BOARD'!#REF! -> #REF! | H132: ='THE BOARD'!#REF! -> #REF! | I132: ='THE BOARD'!#REF! -> #REF! | J132: ='THE BOARD'!#REF! -> #REF! | K132: ='THE BOARD'!#REF! -> #REF!
A133: ='THE BOARD'!#REF! -> #REF! | B133: ='THE BOARD'!#REF! -> #REF! | C133: =IF('THE BOARD'!#REF! = "NESTED","",IF('THE BOARD'!#REF!<>"",'THE BOARD'!#REF!+0.72,"")) -> #REF! | D133: =IF(C133<>"", IF('THE BOARD'!#REF! = "NESTED","",'THE BOARD'!#REF! + IF(C133<>"", 0.72,0)),"") -> #REF! | E133: ='THE BOARD'!#REF! -> #REF! | F133: ='THE BOARD'!#REF! -> #REF! | G133: ='THE BOARD'!#REF! -> #REF! | H133: ='THE BOARD'!#REF! -> #REF! | I133: ='THE BOARD'!#REF! -> #REF! | J133: ='THE BOARD'!#REF! -> #REF! | K133: ='THE BOARD'!#REF! -> #REF!
A134: ='THE BOARD'!#REF! -> #REF! | B134: ='THE BOARD'!#REF! -> #REF! | C134: =IF('THE BOARD'!#REF! = "NESTED","",IF('THE BOARD'!#REF!<>"",'THE BOARD'!#REF!+0.72,"")) -> #REF! | D134: =IF(C134<>"", IF('THE BOARD'!#REF! = "NESTED","",'THE BOARD'!#REF! + IF(C134<>"", 0.72,0)),"") -> #REF! | E134: ='THE BOARD'!#REF! -> #REF! | F134: ='THE BOARD'!#REF! -> #REF! | G134: ='THE BOARD'!#REF! -> #REF! | H134: ='THE BOARD'!#REF! -> #REF! | I134: ='THE BOARD'!#REF! -> #REF! | J134: ='THE BOARD'!#REF! -> #REF! | K134: ='THE BOARD'!#REF! -> #REF!
A135: ='THE BOARD'!#REF! -> #REF! | B135: ='THE BOARD'!#REF! -> #REF! | C135: =IF('THE BOARD'!#REF! = "NESTED","",IF('THE BOARD'!#REF!<>"",'THE BOARD'!#REF!+0.72,"")) -> #REF! | D135: =IF(C135<>"", IF('THE BOARD'!#REF! = "NESTED","",'THE BOARD'!#REF! + IF(C135<>"", 0.72,0)),"") -> #REF! | E135: ='THE BOARD'!#REF! -> #REF! | F135: ='THE BOARD'!#REF! -> #REF! | G135: ='THE BOARD'!#REF! -> #REF! | H135: ='THE BOARD'!#REF! -> #REF! | I135: ='THE BOARD'!#REF! -> #REF! | J135: ='THE BOARD'!#REF! -> #REF! | K135: ='THE BOARD'!#REF! -> #REF!
A136: ='THE BOARD'!#REF! -> #REF! | B136: ='THE BOARD'!#REF! -> #REF! | C136: =IF('THE BOARD'!#REF! = "NESTED","",IF('THE BOARD'!#REF!<>"",'THE BOARD'!#REF!+0.72,"")) -> #REF! | D136: =IF(C136<>"", IF('THE BOARD'!#REF! = "NESTED","",'THE BOARD'!#REF! + IF(C136<>"", 0.72,0)),"") -> #REF! | E136: ='THE BOARD'!#REF! -> #REF! | F136: ='THE BOARD'!#REF! -> #REF! | G136: ='THE BOARD'!#REF! -> #REF! | H136: ='THE BOARD'!#REF! -> #REF! | I136: ='THE BOARD'!#REF! -> #REF! | J136: ='THE BOARD'!#REF! -> #REF! | K136: ='THE BOARD'!#REF! -> #REF!
A137: ='THE BOARD'!#REF! -> #REF! | B137: ='THE BOARD'!#REF! -> #REF! | C137: =IF('THE BOARD'!#REF! = "NESTED","",IF('THE BOARD'!#REF!<>"",'THE BOARD'!#REF!+0.72,"")) -> #REF! | D137: =IF(C137<>"", IF('THE BOARD'!#REF! = "NESTED","",'THE BOARD'!#REF! + IF(C137<>"", 0.72,0)),"") -> #REF! | E137: ='THE BOARD'!#REF! -> #REF! | F137: ='THE BOARD'!#REF! -> #REF! | G137: ='THE BOARD'!#REF! -> #REF! | H137: ='THE BOARD'!#REF! -> #REF! | I137: ='THE BOARD'!#REF! -> #REF! | J137: ='THE BOARD'!#REF! -> #REF! | K137: ='THE BOARD'!#REF! -> #REF!
A138: ='THE BOARD'!#REF! -> #REF! | B138: ='THE BOARD'!#REF! -> #REF! | C138: =IF('THE BOARD'!#REF! = "NESTED","",IF('THE BOARD'!#REF!<>"",'THE BOARD'!#REF!+0.72,"")) -> #REF! | D138: =IF(C138<>"", IF('THE BOARD'!#REF! = "NESTED","",'THE BOARD'!#REF! + IF(C138<>"", 0.72,0)),"") -> #REF! | E138: ='THE BOARD'!#REF! -> #REF! | F138: ='THE BOARD'!#REF! -> #REF! | G138: ='THE BOARD'!#REF! -> #REF! | H138: ='THE BOARD'!#REF! -> #REF! | I138: ='THE BOARD'!#REF! -> #REF! | J138: ='THE BOARD'!#REF! -> #REF! | K138: ='THE BOARD'!#REF! -> #REF!
A139: ='THE BOARD'!#REF! -> #REF! | B139: ='THE BOARD'!#REF! -> #REF! | C139: =IF('THE BOARD'!#REF! = "NESTED","",IF('THE BOARD'!#REF!<>"",'THE BOARD'!#REF!+0.72,"")) -> #REF! | D139: =IF(C139<>"", IF('THE BOARD'!#REF! = "NESTED","",'THE BOARD'!#REF! + IF(C139<>"", 0.72,0)),"") -> #REF! | E139: ='THE BOARD'!#REF! -> #REF! | F139: ='THE BOARD'!#REF! -> #REF! | G139: ='THE BOARD'!#REF! -> #REF! | H139: ='THE BOARD'!#REF! -> #REF! | I139: ='THE BOARD'!#REF! -> #REF! | J139: ='THE BOARD'!#REF! -> #REF! | K139: ='THE BOARD'!#REF! -> #REF!
A140: ='THE BOARD'!#REF! -> #REF! | B140: ='THE BOARD'!#REF! -> #REF! | C140: =IF('THE BOARD'!#REF! = "NESTED","",IF('THE BOARD'!#REF!<>"",'THE BOARD'!#REF!+0.72,"")) -> #REF! | D140: =IF(C140<>"", IF('THE BOARD'!#REF! = "NESTED","",'THE BOARD'!#REF! + IF(C140<>"", 0.72,0)),"") -> #REF! | E140: ='THE BOARD'!#REF! -> #REF! | F140: ='THE BOARD'!#REF! -> #REF! | G140: ='THE BOARD'!#REF! -> #REF! | H140: ='THE BOARD'!#REF! -> #REF! | I140: ='THE BOARD'!#REF! -> #REF! | J140: ='THE BOARD'!#REF! -> #REF! | K140: ='THE BOARD'!#REF! -> #REF!
... A155: ='THE BOARD'!#REF! -> #REF! | B155: ='THE BOARD'!#REF! -> #REF! | C155: =IF('THE BOARD'!#REF! = "NESTED","",IF('THE BOARD'!#REF!<>"",'THE BOARD'!#REF!+0.72,"")) -> #REF! | D155: =IF(C155<>"", IF('THE BOARD'!#REF! = "NESTED","",'THE BOARD'!#REF! + IF(C155<>"", 0.72,0)),"") -> #REF! | E155: ='THE BOARD'!#REF! -> #REF! | F155: ='THE BOARD'!#REF! -> #REF! | G155: ='THE BOARD'!#REF! -> #REF! | H155: ='THE BOARD'!#REF! -> #REF! | I155: ='THE BOARD'!#REF! -> #REF! | J155: ='THE BOARD'!#REF! -> #REF! | K155: ='THE BOARD'!#REF! -> #REF!
A156: =#REF! -> #REF! | B156: =#REF! -> #REF! | C156: =IF(#REF! = "NESTED","",IF(#REF!<>"",#REF!+0.72,"")) -> #REF! | D156: =IF(C156<>"", IF(#REF! = "NESTED","",#REF! + IF(C156<>"", 0.72,0)),"") -> #REF! | E156: =#REF! -> #REF! | F156: =#REF! -> #REF! | G156: =#REF! -> #REF! | H156: =#REF! -> #REF! | I156: =#REF! -> #REF! | J156: =#REF! -> #REF! | K156: =#REF! -> #REF!
A157: ='THE BOARD'!#REF! -> #REF! | B157: ='THE BOARD'!#REF! -> #REF! | C157: =IF('THE BOARD'!#REF! = "NESTED","",IF('THE BOARD'!#REF!<>"",'THE BOARD'!#REF!+0.72,"")) -> #REF! | D157: =IF(C157<>"", IF('THE BOARD'!#REF! = "NESTED","",'THE BOARD'!#REF! + IF(C157<>"", 0.72,0)),"") -> #REF! | E157: ='THE BOARD'!#REF! -> #REF! | F157: ='THE BOARD'!#REF! -> #REF! | G157: ='THE BOARD'!#REF! -> #REF! | H157: ='THE BOARD'!#REF! -> #REF! | I157: ='THE BOARD'!#REF! -> #REF! | J157: ='THE BOARD'!#REF! -> #REF! | K157: ='THE BOARD'!#REF! -> #REF!
A158: ='THE BOARD'!#REF! -> #REF! | B158: ='THE BOARD'!#REF! -> #REF! | C158: =IF('THE BOARD'!#REF! = "NESTED","",IF('THE BOARD'!#REF!<>"",'THE BOARD'!#REF!+0.72,"")) -> #REF! | D158: =IF(C158<>"", IF('THE BOARD'!#REF! = "NESTED","",'THE BOARD'!#REF! + IF(C158<>"", 0.72,0)),"") -> #REF! | E158: ='THE BOARD'!#REF! -> #REF! | F158: ='THE BOARD'!#REF! -> #REF! | G158: ='THE BOARD'!#REF! -> #REF! | H158: ='THE BOARD'!#REF! -> #REF! | I158: ='THE BOARD'!#REF! -> #REF! | J158: ='THE BOARD'!#REF! -> #REF! | K158: ='THE BOARD'!#REF! -> #REF!
A159: ='THE BOARD'!#REF! -> #REF! | B159: ='THE BOARD'!#REF! -> #REF! | C159: =IF('THE BOARD'!#REF! = "NESTED","",IF('THE BOARD'!#REF!<>"",'THE BOARD'!#REF!+0.72,"")) -> #REF! | D159: =IF(C159<>"", IF('THE BOARD'!#REF! = "NESTED","",'THE BOARD'!#REF! + IF(C159<>"", 0.72,0)),"") -> #REF! | E159: ='THE BOARD'!#REF! -> #REF! | F159: ='THE BOARD'!#REF! -> #REF! | G159: ='THE BOARD'!#REF! -> #REF! | H159: ='THE BOARD'!#REF! -> #REF! | I159: ='THE BOARD'!#REF! -> #REF! | J159: ='THE BOARD'!#REF! -> #REF! | K159: ='THE BOARD'!#REF! -> #REF!
A160: ='THE BOARD'!#REF! -> #REF! | B160: ='THE BOARD'!#REF! -> #REF! | C160: =IF('THE BOARD'!#REF! = "NESTED","",IF('THE BOARD'!#REF!<>"",'THE BOARD'!#REF!+0.72,"")) -> #REF! | D160: =IF(C160<>"", IF('THE BOARD'!#REF! = "NESTED","",'THE BOARD'!#REF! + IF(C160<>"", 0.72,0)),"") -> #REF! | E160: ='THE BOARD'!#REF! -> #REF! | F160: ='THE BOARD'!#REF! -> #REF! | G160: ='THE BOARD'!#REF! -> #REF! | H160: ='THE BOARD'!#REF! -> #REF! | I160: ='THE BOARD'!#REF! -> #REF! | J160: ='THE BOARD'!#REF! -> #REF! | K160: ='THE BOARD'!#REF! -> #REF!
A161: ='THE BOARD'!#REF! -> #REF! | B161: ='THE BOARD'!#REF! -> #REF! | C161: =IF('THE BOARD'!#REF! = "NESTED","",IF('THE BOARD'!#REF!<>"",'THE BOARD'!#REF!+0.72,"")) -> #REF! | D161: =IF(C161<>"", IF('THE BOARD'!#REF! = "NESTED","",'THE BOARD'!#REF! + IF(C161<>"", 0.72,0)),"") -> #REF! | E161: ='THE BOARD'!#REF! -> #REF! | F161: ='THE BOARD'!#REF! -> #REF! | G161: ='THE BOARD'!#REF! -> #REF! | H161: ='THE BOARD'!#REF! -> #REF! | I161: ='THE BOARD'!#REF! -> #REF! | J161: ='THE BOARD'!#REF! -> #REF! | K161: ='THE BOARD'!#REF! -> #REF!
A162: ='THE BOARD'!#REF! -> #REF! | B162: ='THE BOARD'!#REF! -> #REF! | C162: =IF('THE BOARD'!#REF! = "NESTED","",IF('THE BOARD'!#REF!<>"",'THE BOARD'!#REF!+0.72,"")) -> #REF! | D162: =IF(C162<>"", IF('THE BOARD'!#REF! = "NESTED","",'THE BOARD'!#REF! + IF(C162<>"", 0.72,0)),"") -> #REF! | E162: ='THE BOARD'!#REF! -> #REF! | F162: ='THE BOARD'!#REF! -> #REF! | G162: ='THE BOARD'!#REF! -> #REF! | H162: ='THE BOARD'!#REF! -> #REF! | I162: ='THE BOARD'!#REF! -> #REF! | J162: ='THE BOARD'!#REF! -> #REF! | K162: ='THE BOARD'!#REF! -> #REF!
A163: ='THE BOARD'!#REF! -> #REF! | B163: ='THE BOARD'!#REF! -> #REF! | C163: =IF('THE BOARD'!#REF! = "NESTED","",IF('THE BOARD'!#REF!<>"",'THE BOARD'!#REF!+0.72,"")) -> #REF! | D163: =IF(C163<>"", IF('THE BOARD'!#REF! = "NESTED","",'THE BOARD'!#REF! + IF(C163<>"", 0.72,0)),"") -> #REF! | E163: ='THE BOARD'!#REF! -> #REF! | F163: ='THE BOARD'!#REF! -> #REF! | G163: ='THE BOARD'!#REF! -> #REF! | H163: ='THE BOARD'!#REF! -> #REF! | I163: ='THE BOARD'!#REF! -> #REF! | J163: ='THE BOARD'!#REF! -> #REF! | K163: ='THE BOARD'!#REF! -> #REF!
A164: ='THE BOARD'!#REF! -> #REF! | B164: ='THE BOARD'!#REF! -> #REF! | C164: =IF('THE BOARD'!#REF! = "NESTED","",IF('THE BOARD'!#REF!<>"",'THE BOARD'!#REF!+0.72,"")) -> #REF! | D164: =IF(C164<>"", IF('THE BOARD'!#REF! = "NESTED","",'THE BOARD'!#REF! + IF(C164<>"", 0.72,0)),"") -> #REF! | E164: ='THE BOARD'!#REF! -> #REF! | F164: ='THE BOARD'!#REF! -> #REF! | G164: ='THE BOARD'!#REF! -> #REF! | H164: ='THE BOARD'!#REF! -> #REF! | I164: ='THE BOARD'!#REF! -> #REF! | J164: ='THE BOARD'!#REF! -> #REF! | K164: ='THE BOARD'!#REF! -> #REF!
A165: ='THE BOARD'!#REF! -> #REF! | B165: ='THE BOARD'!#REF! -> #REF! | C165: =IF('THE BOARD'!#REF! = "NESTED","",IF('THE BOARD'!#REF!<>"",'THE BOARD'!#REF!+0.72,"")) -> #REF! | D165: =IF(C165<>"", IF('THE BOARD'!#REF! = "NESTED","",'THE BOARD'!#REF! + IF(C165<>"", 0.72,0)),"") -> #REF! | E165: ='THE BOARD'!#REF! -> #REF! | F165: ='THE BOARD'!#REF! -> #REF! | G165: ='THE BOARD'!#REF! -> #REF! | H165: ='THE BOARD'!#REF! -> #REF! | I165: ='THE BOARD'!#REF! -> #REF! | J165: ='THE BOARD'!#REF! -> #REF! | K165: ='THE BOARD'!#REF! -> #REF!
A166: ='THE BOARD'!#REF! -> #REF! | B166: ='THE BOARD'!#REF! -> #REF! | C166: =IF('THE BOARD'!#REF! = "NESTED","",IF('THE BOARD'!#REF!<>"",'THE BOARD'!#REF!+0.72,"")) -> #REF! | D166: =IF(C166<>"", IF('THE BOARD'!#REF! = "NESTED","",'THE BOARD'!#REF! + IF(C166<>"", 0.72,0)),"") -> #REF! | E166: ='THE BOARD'!#REF! -> #REF! | F166: ='THE BOARD'!#REF! -> #REF! | G166: ='THE BOARD'!#REF! -> #REF! | H166: ='THE BOARD'!#REF! -> #REF! | I166: ='THE BOARD'!#REF! -> #REF! | J166: ='THE BOARD'!#REF! -> #REF! | K166: ='THE BOARD'!#REF! -> #REF!
A167: ='THE BOARD'!#REF! -> #REF! | B167: ='THE BOARD'!#REF! -> #REF! | C167: =IF('THE BOARD'!#REF! = "NESTED","",IF('THE BOARD'!#REF!<>"",'THE BOARD'!#REF!+0.72,"")) -> #REF! | D167: =IF(C167<>"", IF('THE BOARD'!#REF! = "NESTED","",'THE BOARD'!#REF! + IF(C167<>"", 0.72,0)),"") -> #REF! | E167: ='THE BOARD'!#REF! -> #REF! | F167: ='THE BOARD'!#REF! -> #REF! | G167: ='THE BOARD'!#REF! -> #REF! | H167: ='THE BOARD'!#REF! -> #REF! | I167: ='THE BOARD'!#REF! -> #REF! | J167: ='THE BOARD'!#REF! -> #REF! | K167: ='THE BOARD'!#REF! -> #REF!
...
